# نحوه نوشتن تست‌ها

تست‌ها در **Rust** توابعی هستند که بررسی می‌کنند آیا کد غیرتستی به‌صورت مورد انتظار عمل می‌کند یا خیر. بدنه توابع تست معمولاً سه عمل را انجام می‌دهند:

1. تنظیم هرگونه داده یا حالت مورد نیاز.
2. اجرای کدی که می‌خواهید تست کنید.
3. تأیید اینکه نتایج همان چیزی هستند که انتظار دارید.

بیایید به ویژگی‌هایی که **Rust** به‌طور خاص برای نوشتن تست‌هایی که این اقدامات را انجام می‌دهند ارائه می‌دهد نگاه کنیم، از جمله ویژگی `test`، چند ماکرو، و ویژگی `should_panic`.

## آناتومی یک تابع تست

به ساده‌ترین شکل، یک تست در **Rust** تابعی است که با ویژگی `test` حاشیه‌نویسی شده است. ویژگی‌ها (attributes) متادیتاهایی درباره قطعات کد **Rust** هستند؛ یک مثال، ویژگی `derive` است که با ساختارها در فصل پنجم استفاده کردیم. برای تبدیل یک تابع به تابع تست، `#[test]` را در خط قبل از `fn` اضافه کنید. وقتی تست‌های خود را با دستور `cargo test` اجرا می‌کنید، **Rust** یک باینری اجرای تست می‌سازد که توابع حاشیه‌نویسی‌شده را اجرا می‌کند و گزارش می‌دهد که آیا هر تابع تست موفق شده یا شکست خورده است.

هرگاه یک پروژه کتابخانه‌ای جدید با **Cargo** ایجاد کنیم، یک ماژول تست با یک تابع تست در آن به‌صورت خودکار برای ما تولید می‌شود. این ماژول الگویی برای نوشتن تست‌های شما ارائه می‌دهد تا هر بار که پروژه جدیدی شروع می‌کنید، نیازی به جستجوی ساختار و نحو دقیق نداشته باشید. می‌توانید به تعداد دلخواه تابع تست اضافی و ماژول تست اضافه کنید!

ما برخی جنبه‌های نحوه عملکرد تست‌ها را با آزمایش الگوی تست بررسی خواهیم کرد قبل از اینکه واقعاً کدی را تست کنیم. سپس چند تست واقعی خواهیم نوشت که کدی که نوشته‌ایم را فراخوانی می‌کنند و تأیید می‌کنند که رفتارش درست است.

بیایید یک پروژه کتابخانه‌ای جدید به نام `adder` ایجاد کنیم که دو عدد را جمع می‌کند:

```bash
$ cargo new adder --lib
     Created library `adder` project
$ cd adder
```

محتوای فایل `src/lib.rs` در کتابخانه `adder` شما باید شبیه **جدول 11-1** باشد.

**فایل: src/lib.rs**

```rust
pub fn add(left: u64, right: u64) -> u64 {
    left + right
}

#[cfg(test)]
mod tests {
    use super::*;

    #[test]
    fn it_works() {
        let result = add(2, 2);
        assert_eq!(result, 4);
    }
}
```

**جدول 11-1**: کدی که به‌صورت خودکار توسط `cargo new` تولید شده است

فایل با یک تابع نمونه `add` شروع می‌شود، تا چیزی برای تست داشته باشیم.

برای حالا، فقط روی تابع `it_works` تمرکز می‌کنیم. به حاشیه‌نویسی `#[test]` توجه کنید: این ویژگی نشان می‌دهد که این یک تابع تست است، بنابراین اجرای تست می‌داند که این تابع را به‌عنوان یک تست در نظر بگیرد. ممکن است توابع غیرتستی نیز در ماژول `tests` داشته باشیم تا سناریوهای مشترک را تنظیم کنیم یا عملیات‌های مشترک را انجام دهیم، بنابراین همیشه باید مشخص کنیم که کدام توابع تست هستند.

بدنه تابع نمونه از ماکرو `assert_eq!` استفاده می‌کند تا تأیید کند که `result`، که شامل نتیجه فراخوانی `add` با 2 و 2 است، برابر با 4 است. این تأیید به‌عنوان مثالی از فرمت یک تست معمولی عمل می‌کند. بیایید آن را اجرا کنیم تا ببینیم که این تست موفق می‌شود.

دستور `cargo test` همه تست‌ها را در پروژه ما اجرا می‌کند، همان‌طور که در **جدول 11-2** نشان داده شده است.

```bash
$ cargo test
   Compiling adder v0.1.0 (file:///projects/adder)
    Finished `test` profile [unoptimized + debuginfo] target(s) in 0.57s
     Running unittests src/lib.rs (file:///projects/adder/target/debug/deps/adder-40313d497ef8f64e)

running 1 test
test tests::it_works ... ok

test result: ok. 1 passed; 0 failed; 0 ignored; 0 measured; 0 filtered out; finished in 0.00s

   Doc-tests adder

running 0 tests

test result: ok. 0 passed; 0 failed; 0 ignored; 0 measured; 0 filtered out; finished in 0.00s
```

**جدول 11-2**: خروجی حاصل از اجرای تست تولیدشده به‌صورت خودکار

**Cargo** تست را کامپایل و اجرا کرد. خط `running 1 test` را می‌بینیم. خط بعدی نام تابع تست تولیدشده را نشان می‌دهد، به نام `tests::it_works`، و اینکه نتیجه اجرای آن تست `ok` است. خلاصه کلی نتیجه تست: `ok.` به این معناست که همه تست‌ها موفق شده‌اند، و بخشی که می‌گوید `1 passed; 0 failed` تعداد تست‌هایی که موفق یا شکست خورده‌اند را جمع‌بندی می‌کند.

می‌توان یک تست را طوری علامت‌گذاری کرد که در یک نمونه خاص اجرا نشود؛ این موضوع را در بخش «نادیده گرفتن برخی تست‌ها مگر اینکه صراحتاً درخواست شوند» بعداً در این فصل پوشش خواهیم داد. چون اینجا این کار را نکرده‌ایم، خلاصه نشان می‌دهد `0 ignored`. همچنین می‌توانیم آرگومانی به دستور `cargo test` پاس دهیم تا فقط تست‌هایی اجرا شوند که نامشان با یک رشته مطابقت دارد؛ این به نام فیلتر کردن شناخته می‌شود و در بخش «اجرای زیرمجموعه‌ای از تست‌ها بر اساس نام» آن را پوشش خواهیم داد. اینجا تست‌های در حال اجرا را فیلتر نکرده‌ایم، بنابراین انتهای خلاصه نشان می‌دهد `0 filtered out`.

آمار `0 measured` برای تست‌های معیاری (benchmark tests) است که عملکرد را اندازه‌گیری می‌کنند. تست‌های معیاری، تا زمان نگارش این متن، فقط در **Rust** شبانه (nightly) در دسترس هستند. برای اطلاعات بیشتر به مستندات درباره تست‌های معیاری مراجعه کنید.

بخش بعدی خروجی تست که با `Doc-tests adder` شروع می‌شود، برای نتایج هرگونه تست مستندات است. ما هنوز هیچ تست مستنداتی نداریم، اما **Rust** می‌تواند هر نمونه کدی که در مستندات API ما ظاهر می‌شود را کامپایل کند. این ویژگی به نگه‌داشتن همگام‌سازی مستندات و کد شما کمک می‌کند! ما در بخش «نظرات مستندات به‌عنوان تست‌ها» در فصل چهاردهم نحوه نوشتن تست‌های مستندات را بحث خواهیم کرد. برای حالا، خروجی `Doc-tests` را نادیده می‌گیریم.

بیایید شروع به سفارشی‌سازی تست برای نیازهای خودمان کنیم. ابتدا، نام تابع `it_works` را به نامی متفاوت، مانند `exploration`، تغییر دهید، مانند این:

**فایل: src/lib.rs**

```rust
pub fn add(left: u64, right: u64) -> u64 {
    left + right
}

#[cfg(test)]
mod tests {
    use super::*;

    #[test]
    fn exploration() {
        let result = add(2, 2);
        assert_eq!(result, 4);
    }
}
```

سپس دوباره `cargo test` را اجرا کنید. خروجی اکنون به‌جای `it_works`، `exploration` را نشان می‌دهد:

```bash
$ cargo test
   Compiling adder v0.1.0 (file:///projects/adder)
    Finished `test` profile [unoptimized + debuginfo] target(s) in 0.59s
     Running unittests src/lib.rs (target/debug/deps/adder-92948b65e88960b4)

running 1 test
test tests::exploration ... ok

test result: ok. 1 passed; 0 failed; 0 ignored; 0 measured; 0 filtered out; finished in 0.00s

   Doc-tests adder

running 0 tests

test result: ok. 0 passed; 0 failed; 0 ignored; 0 measured; 0 filtered out; finished in 0.00s
```

حالا یک تست دیگر اضافه خواهیم کرد، اما این بار تستی خواهیم ساخت که شکست می‌خورد! تست‌ها وقتی چیزی در تابع تست باعث وحشت (panic) شود شکست می‌خورند. هر تست در یک نخ (thread) جدید اجرا می‌شود، و وقتی نخ اصلی می‌بیند که یک نخ تست مرده است، تست به‌عنوان شکست‌خورده علامت‌گذاری می‌شود. در فصل نهم، صحبت کردیم که ساده‌ترین راه برای ایجاد وحشت، فراخوانی ماکرو `panic!` است. تست جدید را به‌عنوان تابعی به نام `another` وارد کنید، بنابراین فایل `src/lib.rs` شما شبیه **جدول 11-3** خواهد بود.

**فایل: src/lib.rs**

**این کد باعث وحشت می‌شود!**

```rust
pub fn add(left: u64, right: u64) -> u64 {
    left + right
}

#[cfg(test)]
mod tests {
    use super::*;

    #[test]
    fn exploration() {
        let result = add(2, 2);
        assert_eq!(result, 4);
    }

    #[test]
    fn another() {
        panic!("Make this test fail");
    }
}
```

**جدول 11-3**: افزودن یک تست دوم که به دلیل فراخوانی ماکرو `panic!` شکست خواهد خورد

دوباره تست‌ها را با استفاده از `cargo test` اجرا کنید. خروجی باید شبیه **جدول 11-4** باشد، که نشان می‌دهد تست `exploration` ما موفق شده و `another` شکست خورده است.

```bash
$ cargo test
   Compiling adder v0.1.0 (file:///projects/adder)
    Finished `test` profile [unoptimized + debuginfo] target(s) in 0.72s
     Running unittests src/lib.rs (target/debug/deps/adder-92948b65e88960b4)

running 2 tests
test tests::another ... FAILED
test tests::exploration ... ok

failures:

---- tests::another stdout ----

thread 'tests::another' panicked at src/lib.rs:17:9:
Make this test fail
note: run with `RUST_BACKTRACE=1` environment variable to display a backtrace


failures:
    tests::another

test result: FAILED. 1 passed; 1 failed; 0 ignored; 0 measured; 0 filtered out; finished in 0.00s

error: test failed, to rerun pass `--lib`
```

**جدول 11-4**: نتایج تست وقتی یک تست موفق می‌شود و یک تست شکست می‌خورد

به‌جای `ok`، خط `test tests::another` نشان می‌دهد `FAILED`. دو بخش جدید بین نتایج فردی و خلاصه ظاهر می‌شوند: اولی دلیل دقیق هر شکست تست را نمایش می‌دهد. در این مورد، ما جزئیات را دریافت می‌کنیم که `another` شکست خورده است زیرا در خط 17 در فایل `src/lib.rs` وحشت کرده است با پیام `Make this test fail`. بخش بعدی فقط نام‌های همه تست‌های شکست‌خورده را فهرست می‌کند، که وقتی تست‌های زیادی و خروجی‌های شکست دقیق زیادی وجود دارد مفید است. می‌توانیم از نام یک تست شکست‌خورده استفاده کنیم تا فقط آن تست را اجرا کنیم تا دیباگ کردن آن آسان‌تر شود؛ در بخش «کنترل نحوه اجرای تست‌ها» درباره راه‌های اجرای تست‌ها بیشتر صحبت خواهیم کرد.

خط خلاصه در انتها نمایش داده می‌شود: به‌طور کلی، نتیجه تست ما `FAILED` است. ما یک تست موفق و یک تست شکست‌خورده داشتیم.

اکنون که دیده‌اید نتایج تست در سناریوهای مختلف چگونه به نظر می‌رسند، بیایید به برخی ماکروهای غیر از `panic!` که در تست‌ها مفید هستند نگاه کنیم.

## بررسی نتایج با ماکرو `assert!`

ماکرو `assert!`، که توسط کتابخانه استاندارد ارائه شده است، زمانی مفید است که بخواهید اطمینان حاصل کنید که یک شرط در تست به `true` ارزیابی می‌شود. ما به ماکرو `assert!` آرگومانی می‌دهیم که به یک مقدار بولی ارزیابی می‌شود. اگر مقدار `true` باشد، هیچ اتفاقی نمی‌افتد و تست موفق می‌شود. اگر مقدار `false` باشد، ماکرو `assert!` تابع `panic!` را فراخوانی می‌کند تا تست شکست بخورد. استفاده از ماکرو `assert!` به ما کمک می‌کند بررسی کنیم که کدمان به روشی که در نظر داریم عمل می‌کند.

در فصل پنجم، **جدول 5-15**، ما از یک ساختار `Rectangle` و یک متد `can_hold` استفاده کردیم، که در اینجا در **جدول 11-5** تکرار شده‌اند. بیایید این کد را در فایل `src/lib.rs` قرار دهیم، سپس چند تست برای آن با استفاده از ماکرو `assert!` بنویسیم.

**فایل: src/lib.rs**

```rust
#[derive(Debug)]
struct Rectangle {
    width: u32,
    height: u32,
}

impl Rectangle {
    fn can_hold(&self, other: &Rectangle) -> bool {
        self.width > other.width && self.height > other.height
    }
}
```

**جدول 11-5**: ساختار `Rectangle` و متد `can_hold` آن از فصل پنجم

متد `can_hold` یک مقدار بولی برمی‌گرداند، که آن را به یک مورد استفاده عالی برای ماکرو `assert!` تبدیل می‌کند. در **جدول 11-6**، ما تستی می‌نویسیم که متد `can_hold` را با ایجاد یک نمونه `Rectangle` که عرض 8 و ارتفاع 7 دارد آزمایش می‌کند و تأیید می‌کند که می‌تواند یک نمونه `Rectangle` دیگر با عرض 5 و ارتفاع 1 را در خود جای دهد.

**فایل: src/lib.rs**

```rust
#[cfg(test)]
mod tests {
    use super::*;

    #[test]
    fn larger_can_hold_smaller() {
        let larger = Rectangle {
            width: 8,
            height: 7,
        };
        let smaller = Rectangle {
            width: 5,
            height: 1,
        };

        assert!(larger.can_hold(&smaller));
    }
}
```

**جدول 11-6**: تستی برای `can_hold` که بررسی می‌کند آیا یک مستطیل بزرگ‌تر واقعاً می‌تواند یک مستطیل کوچک‌تر را در خود جای دهد

به خط `use super::*;` در داخل ماژول `tests` توجه کنید. ماژول `tests` یک ماژول معمولی است که از قوانین دیدپذیری معمول که در فصل هفتم در بخش «مسیرها برای ارجاع به یک آیتم در درخت ماژول» پوشش دادیم پیروی می‌کند. چون ماژول `tests` یک ماژول درونی است، باید کد تحت تست در ماژول بیرونی را به حوزه ماژول درونی بیاوریم. ما اینجا از یک گلوب استفاده می‌کنیم، بنابراین هر چیزی که در ماژول بیرونی تعریف کنیم برای این ماژول `tests` در دسترس است.

ما تست خود را `larger_can_hold_smaller` نام‌گذاری کرده‌ایم، و دو نمونه `Rectangle` که نیاز داریم را ایجاد کرده‌ایم. سپس ماکرو `assert!` را فراخوانی کردیم و نتیجه فراخوانی `larger.can_hold(&smaller)` را به آن پاس دادیم. این عبارت باید `true` برگرداند، بنابراین تست ما باید موفق شود. بیایید ببینیم!

```bash
$ cargo test
   Compiling rectangle v0.1.0 (file:///projects/rectangle)
    Finished `test` profile [unoptimized + debuginfo] target(s) in 0.66s
     Running unittests src/lib.rs (target/debug/deps/rectangle-6584c4561e48942e)

running 1 test
test tests::larger_can_hold_smaller ... ok

test result: ok. 1 passed; 0 failed; 0 ignored; 0 measured; 0 filtered out; finished in 0.00s

   Doc-tests rectangle

running 0 tests

test result: ok. 0 passed; 0 failed; 0 ignored; 0 measured; 0 filtered out; finished in 0.00s
```

موفق شد! بیایید یک تست دیگر اضافه کنیم، این بار تأیید می‌کنیم که یک مستطیل کوچک‌تر نمی‌تواند یک مستطیل بزرگ‌تر را در خود جای دهد:

**فایل: src/lib.rs**

```rust
#[cfg(test)]
mod tests {
    use super::*;

    #[test]
    fn larger_can_hold_smaller() {
        // --قطعه کد حذف شده--
    }

    #[test]
    fn smaller_cannot_hold_larger() {
        let larger = Rectangle {
            width: 8,
            height: 7,
        };
        let smaller = Rectangle {
            width: 5,
            height: 1,
        };

        assert!(!smaller.can_hold(&larger));
    }
}
```

چون نتیجه درست تابع `can_hold` در این مورد `false` است، باید آن نتیجه را قبل از پاس دادن به ماکرو `assert!` نفی کنیم. در نتیجه، تست ما اگر `can_hold` مقدار `false` برگرداند موفق خواهد شد:

```bash
$ cargo test
   Compiling rectangle v0.1.0 (file:///projects/rectangle)
    Finished `test` profile [unoptimized + debuginfo] target(s) in 0.66s
     Running unittests src/lib.rs (target/debug/deps/rectangle-6584c4561e48942e)

running 2 tests
test tests::larger_can_hold_smaller ... ok
test tests::smaller_cannot_hold_larger ... ok

test result: ok. 2 passed; 0 failed; 0 ignored; 0 measured; 0 filtered out; finished in 0.00s

   Doc-tests rectangle

running 0 tests

test result: ok. 0 passed; 0 failed; 0 ignored; 0 measured; 0 filtered out; finished in 0.00s
```

دو تست که موفق شدند! حالا بیایید ببینیم وقتی یک باگ در کدمان معرفی می‌کنیم چه اتفاقی برای نتایج تست ما می‌افتد. ما پیاده‌سازی متد `can_hold` را با جایگزین کردن علامت بزرگ‌تر با علامت کوچک‌تر هنگام مقایسه عرض‌ها تغییر خواهیم داد:

**این کد رفتار مورد نظر را تولید نمی‌کند.**

```rust
// --قطعه کد حذف شده--
impl Rectangle {
    fn can_hold(&self, other: &Rectangle) -> bool {
        self.width < other.width && self.height > other.height
    }
}
```

اجرای تست‌ها اکنون تولید می‌کند:

```bash
$ cargo test
   Compiling rectangle v0.1.0 (file:///projects/rectangle)
    Finished `test` profile [unoptimized + debuginfo] target(s) in 0.66s
     Running unittests src/lib.rs (target/debug/deps/rectangle-6584c4561e48942e)

running 2 tests
test tests::larger_can_hold_smaller ... FAILED
test tests::smaller_cannot_hold_larger ... ok

failures:

---- tests::larger_can_hold_smaller stdout ----

thread 'tests::larger_can_hold_smaller' panicked at src/lib.rs:28:9:
assertion failed: larger.can_hold(&smaller)
note: run with `RUST_BACKTRACE=1` environment variable to display a backtrace


failures:
    tests::larger_can_hold_smaller

test result: FAILED. 1 passed; 1 failed; 0 ignored; 0 measured; 0 filtered out; finished in 0.00s

error: test failed, to rerun pass `--lib`
```

تست‌های ما باگ را گرفتند! چون `larger.width` برابر 8 و `smaller.width` برابر 5 است، مقایسه عرض‌ها در `can_hold` اکنون `false` برمی‌گرداند: 8 کوچک‌تر از 5 نیست.

## تست برابری با ماکروهای `assert_eq!` و `assert_ne!`

یک راه رایج برای تأیید عملکرد، تست برابری بین نتیجه کد تحت تست و مقداری است که انتظار دارید کد برگرداند. می‌توانید این کار را با استفاده از ماکرو `assert!` و پاس دادن یک عبارت با استفاده از عملگر `==` انجام دهید. با این حال، این یک تست بسیار رایج است که کتابخانه استاندارد یک جفت ماکرو—`assert_eq!` و `assert_ne!`—را برای انجام این تست به‌صورت راحت‌تر ارائه می‌دهد. این ماکروها دو آرگومان را برای برابری یا نابرابری مقایسه می‌کنند. همچنین اگر تأیید شکست بخورد، این دو مقدار را چاپ می‌کنند، که دیدن دلیل شکست تست را آسان‌تر می‌کند؛ در مقابل، ماکرو `assert!` فقط نشان می‌دهد که یک مقدار `false` برای عبارت `==` دریافت کرده است، بدون چاپ مقادیری که منجر به مقدار `false` شده‌اند.

در **جدول 11-7**، ما تابعی به نام `add_two` می‌نویسیم که 2 را به پارامترش اضافه می‌کند، سپس این تابع را با استفاده از ماکرو `assert_eq!` تست می‌کنیم.

**فایل: src/lib.rs**

```rust
pub fn add_two(a: usize) -> usize {
    a + 2
}

#[cfg(test)]
mod tests {
    use super::*;

    #[test]
    fn it_adds_two() {
        let result = add_two(2);
        assert_eq!(result, 4);
    }
}
```

**جدول 11-7**: تست تابع `add_two` با استفاده از ماکرو `assert_eq!`

بیایید بررسی کنیم که موفق می‌شود!

```bash
$ cargo test
   Compiling adder v0.1.0 (file:///projects/adder)
    Finished `test` profile [unoptimized + debuginfo] target(s) in 0.58s
     Running unittests src/lib.rs (target/debug/deps/adder-92948b65e88960b4)

running 1 test
test tests::it_adds_two ... ok

test result: ok. 1 passed; 0 failed; 0 ignored; 0 measured; 0 filtered out; finished in 0.00s

   Doc-tests adder

running 0 tests

test result: ok. 0 passed; 0 failed; 0 ignored; 0 measured; 0 filtered out; finished in 0.00s
```

ما یک متغیر به نام `result` ایجاد کردیم که نتیجه فراخوانی `add_two(2)` را نگه می‌دارد. سپس `result` و 4 را به‌عنوان آرگومان‌ها به `assert_eq!` پاس دادیم. خط خروجی برای این تست `test tests::it_adds_two ... ok` است، و متن `ok` نشان می‌دهد که تست ما موفق شده است!

بیایید یک باگ به کدمان معرفی کنیم تا ببینیم وقتی `assert_eq!` شکست می‌خورد چه شکلی است. پیاده‌سازی تابع `add_two` را تغییر دهید تا به‌جای آن 3 اضافه کند:

**این کد رفتار مورد نظر را تولید نمی‌کند.**

```rust
pub fn add_two(a: usize) -> usize {
    a + 3
}
```

دوباره تست‌ها را اجرا کنید:

```bash
$ cargo test
   Compiling adder v0.1.0 (file:///projects/adder)
    Finished `test` profile [unoptimized + debuginfo] target(s) in 0.61s
     Running unittests src/lib.rs (target/debug/deps/adder-92948b65e88960b4)

running 1 test
test tests::it_adds_two ... FAILED

failures:

---- tests::it_adds_two stdout ----

thread 'tests::it_adds_two' panicked at src/lib.rs:12:9:
assertion `left == right` failed
  left: 5
 right: 4
note: run with `RUST_BACKTRACE=1` environment variable to display a backtrace


failures:
    tests::it_adds_two

test result: FAILED. 0 passed; 1 failed; 0 ignored; 0 measured; 0 filtered out; finished in 0.00s

error: test failed, to rerun pass `--lib`
```

تست ما باگ را گرفت! تست `it_adds_two` شکست خورد، و پیام به ما می‌گوید که تأییدی که شکست خورده است `assertion `left == right` failed` بود و مقادیر `left` و `right` چیستند. این پیام به ما کمک می‌کند شروع به دیباگ کنیم: آرگومان `left`، جایی که نتیجه فراخوانی `add_two(2)` را داشتیم، 5 بود اما آرگومان `right` 4 بود. می‌توانید تصور کنید که این به‌ویژه وقتی تست‌های زیادی در جریان است بسیار مفید خواهد بود.

توجه داشته باشید که در برخی زبان‌ها و چارچوب‌های تست، پارامترهای توابع تأیید برابری به نام‌های `expected` و `actual` نامیده می‌شوند، و ترتیب مشخص کردن آرگومان‌ها مهم است. با این حال، در **Rust**، آن‌ها `left` و `right` نامیده می‌شوند، و ترتیب مشخص کردن مقدار مورد انتظار و مقداری که کد تولید می‌کند اهمیتی ندارد. ما می‌توانستیم تأیید را در این تست به‌صورت `assert_eq!(add_two(2), result)` بنویسیم، که همان پیام شکست را نمایش می‌دهد که می‌گوید `assertion failed: `(left == right)`` است.

ماکرو `assert_ne!` اگر دو مقداری که به آن می‌دهیم برابر نباشند موفق می‌شود و اگر برابر باشند شکست می‌خورد. این ماکرو برای مواردی که مطمئن نیستیم مقدار چه خواهد بود، اما می‌دانیم مقدار قطعاً نباید چه باشد، بسیار مفید است. برای مثال، اگر تابع‌ای را تست می‌کنیم که تضمین شده ورودی‌اش را به‌نحوی تغییر می‌دهد، اما نحوه تغییر ورودی به روز هفته‌ای که تست‌هایمان را اجرا می‌کنیم بستگی دارد، بهترین چیزی که ممکن است تأیید کنیم این است که خروجی تابع برابر با ورودی نیست.

در زیر سطح، ماکروهای `assert_eq!` و `assert_ne!` به‌ترتیب از عملگرهای `==` و `!=` استفاده می‌کنند. وقتی تأییدها شکست می‌خورند، این ماکروها آرگومان‌هایشان را با استفاده از فرمت دیباگ چاپ می‌کنند، که به این معناست که مقادیری که مقایسه می‌شوند باید ترییت‌های `PartialEq` و `Debug` را پیاده‌سازی کنند. همه نوع‌های اولیه و اکثر نوع‌های کتابخانه استاندارد این ترییت‌ها را پیاده‌سازی می‌کنند. برای ساختارها و شمارش‌هایی که خودتان تعریف می‌کنید، باید `PartialEq` را برای تأیید برابری این نوع‌ها پیاده‌سازی کنید. همچنین باید `Debug` را برای چاپ مقادیر وقتی تأیید شکست می‌خورد پیاده‌سازی کنید. چون هر دو ترییت ترییت‌های قابل‌استخراج هستند، همان‌طور که در **جدول 5-12** در فصل پنجم ذکر شد، این معمولاً به‌سادگی افزودن حاشیه‌نویسی `#[derive(PartialEq, Debug)]` به تعریف ساختار یا شمارش شما است. برای جزئیات بیشتر درباره این و دیگر ترییت‌های قابل‌استخراج، به پیوست C، «ترییت‌های قابل‌استخراج» مراجعه کنید.

## افزودن پیام‌های شکست سفارشی

همچنین می‌توانید یک پیام سفارشی اضافه کنید که همراه با پیام شکست چاپ شود به‌عنوان آرگومان‌های اختیاری برای ماکروهای `assert!`، `assert_eq!`، و `assert_ne!`. هر آرگومانی که بعد از آرگومان‌های مورد نیاز مشخص شود به ماکرو `format!` (که در بخش «پیوست کردن با عملگر + یا ماکرو format!» در فصل هشتم بحث شد) پاس داده می‌شود، بنابراین می‌توانید یک رشته فرمت که شامل جایگاه‌های `{}` و مقادیری برای قرار گرفتن در آن جایگاه‌ها است پاس دهید. پیام‌های سفارشی برای مستند کردن معنای یک تأیید مفید هستند؛ وقتی یک تست شکست می‌خورد، ایده بهتری از مشکل کد خواهید داشت.

برای مثال، فرض کنید تابعی داریم که افراد را با نامشان خوش‌آمد می‌گوید و می‌خواهیم تست کنیم که نامی که به تابع پاس می‌دهیم در خروجی ظاهر می‌شود:

**فایل: src/lib.rs**

```rust
pub fn greeting(name: &str) -> String {
    format!("Hello {name}!")
}

#[cfg(test)]
mod tests {
    use super::*;

    #[test]
    fn greeting_contains_name() {
        let result = greeting("Carol");
        assert!(result.contains("Carol"));
    }
}
```

الزامات این برنامه هنوز توافق نشده‌اند، و ما تقریباً مطمئنیم که متن `Hello` در ابتدای خوش‌آمدگویی تغییر خواهد کرد. تصمیم گرفتیم که نخواهیم تست را وقتی الزامات تغییر می‌کنند به‌روزرسانی کنیم، بنابراین به‌جای بررسی برابری دقیق با مقدار برگردانده‌شده از تابع `greeting`، فقط تأیید خواهیم کرد که خروجی شامل متن پارامتر ورودی است.

حالا بیایید یک باگ به این کد معرفی کنیم با تغییر `greeting` به اینکه `name` را شامل نشود تا ببینیم شکست تست پیش‌فرض چگونه به نظر می‌رسد:

**این کد رفتار مورد نظر را تولید نمی‌کند.**

```rust
pub fn greeting(name: &str) -> String {
    String::from("Hello!")
}
```

اجرای این تست تولید می‌کند:

```bash
$ cargo test
   Compiling greeter v0.1.0 (file:///projects/greeter)
    Finished `test` profile [unoptimized + debuginfo] target(s) in 0.91s
     Running unittests src/lib.rs (target/debug/deps/greeter-170b942eb5bf5e3a)

running 1 test
test tests::greeting_contains_name ... FAILED

failures:

---- tests::greeting_contains_name stdout ----

thread 'tests::greeting_contains_name' panicked at src/lib.rs:12:9:
assertion failed: result.contains("Carol")
note: run with `RUST_BACKTRACE=1` environment variable to display a backtrace


failures:
    tests::greeting_contains_name

test result: FAILED. 0 passed; 1 failed; 0 ignored; 0 measured; 0 filtered out; finished in 0.00s

error: test failed, to rerun pass `--lib`
```

این نتیجه فقط نشان می‌دهد که تأیید شکست خورده است و در کدام خط تأیید قرار دارد. یک پیام شکست مفیدتر مقدار را از تابع `greeting` چاپ می‌کرد. بیایید یک پیام شکست سفارشی اضافه کنیم که از یک رشته فرمت با یک جایگاه تشکیل شده است که با مقدار واقعی که از تابع `greeting` گرفتیم پر شده است:

```rust
#[test]
fn greeting_contains_name() {
    let result = greeting("Carol");
    assert!(
        result.contains("Carol"),
        "Greeting did not contain name, value was `{result}`"
    );
}
```

حالا وقتی تست را اجرا کنیم، پیام خطای اطلاع‌رسان‌تری دریافت خواهیم کرد:

```bash
$ cargo test
   Compiling greeter v0.1.0 (file:///projects/greeter)
    Finished `test` profile [unoptimized + debuginfo] target(s) in 0.93s
     Running unittests src/lib.rs (target/debug/deps/greeter-170b942eb5bf5e3a)

running 1 test
test tests::greeting_contains_name ... FAILED

failures:

---- tests::greeting_contains_name stdout ----

thread 'tests::greeting_contains_name' panicked at src/lib.rs:12:9:
Greeting did not contain name, value was `Hello!`
note: run with `RUST_BACKTRACE=1` environment variable to display a backtrace


failures:
    tests::greeting_contains_name

test result: FAILED. 0 passed; 1 failed; 0 ignored; 0 measured; 0 filtered out; finished in 0.00s

error: test failed, to rerun pass `--lib`
```

ما می‌توانیم مقدار واقعی را که در خروجی تست گرفتیم ببینیم، که به ما کمک می‌کند دیباگ کنیم چه اتفاقی افتاده است به‌جای آنچه انتظار داشتیم اتفاق بیفتد.

## بررسی وحشت‌ها با `should_panic`

علاوه بر بررسی مقادیر بازگشتی، مهم است که بررسی کنیم کد ما شرایط خطا را همان‌طور که انتظار داریم مدیریت می‌کند. برای مثال، نوع `Guess` را که در فصل نهم، **جدول 9-13**، ایجاد کردیم در نظر بگیرید. کد دیگری که از `Guess` استفاده می‌کند به تضمین اینکه نمونه‌های `Guess` فقط مقادیر بین 1 و 100 را شامل می‌شوند وابسته است. ما می‌توانیم تستی بنویسیم که اطمینان حاصل کند تلاش برای ایجاد یک نمونه `Guess` با مقداری خارج از این محدوده باعث وحشت می‌شود.

ما این کار را با افزودن ویژگی `should_panic` به تابع تست خود انجام می‌دهیم. تست اگر کد داخل تابع وحشت کند موفق می‌شود؛ تست اگر کد داخل تابع وحشت نکند شکست می‌خورد.

**جدول 11-8** تستی را نشان می‌دهد که بررسی می‌کند شرایط خطای `Guess::new` وقتی که انتظار داریم اتفاق می‌افتد.

**فایل: src/lib.rs**

```rust
pub struct Guess {
    value: i32,
}

impl Guess {
    pub fn new(value: i32) -> Guess {
        if value < 1 || value > 100 {
            panic!("Guess value must be between 1 and 100, got {value}.");
        }

        Guess { value }
    }
}

#[cfg(test)]
mod tests {
    use super::*;

    #[test]
    #[should_panic]
    fn greater_than_100() {
        Guess::new(200);
    }
}
```

**جدول 11-8**: تست اینکه یک شرط باعث وحشت می‌شود!

ما ویژگی `#[should_panic]` را بعد از ویژگی `#[test]` و قبل از تابع تستی که روی آن اعمال می‌شود قرار می‌دهیم. بیایید نتیجه را وقتی این تست موفق می‌شود ببینیم:

```bash
$ cargo test
   Compiling guessing_game v0.1.0 (file:///projects/guessing_game)
    Finished `test` profile [unoptimized + debuginfo] target(s) in 0.58s
     Running unittests src/lib.rs (target/debug/deps/guessing_game-57d70c3acb738f4d)

running 1 test
test tests::greater_than_100 - should panic ... ok

test result: ok. 1 passed; 0 failed; 0 ignored; 0 measured; 0 filtered out; finished in 0.00s

   Doc-tests guessing_game

running 0 tests

test result: ok. 0 passed; 0 failed; 0 ignored; 0 measured; 0 filtered out; finished in 0.00s
```

به نظر خوب می‌رسد! حالا بیایید یک باگ در کدمان معرفی کنیم با حذف شرطی که تابع `new` اگر مقدار بزرگ‌تر از 100 باشد وحشت می‌کند:

**این کد رفتار مورد نظر را تولید نمی‌کند.**

```rust
// --قطعه کد حذف شده--
impl Guess {
    pub fn new(value: i32) -> Guess {
        if value < 1 {
            panic!("Guess value must be between 1 and 100, got {value}.");
        }

        Guess { value }
    }
}
```

وقتی تست در **جدول 11-8** را اجرا کنیم، شکست خواهد خورد:

```bash
$ cargo test
   Compiling guessing_game v0.1.0 (file:///projects/guessing_game)
    Finished `test` profile [unoptimized + debuginfo] target(s) in 0.62s
     Running unittests src/lib.rs (target/debug/deps/guessing_game-57d70c3acb738f4d)

running 1 test
test tests::greater_than_100 - should panic ... FAILED

failures:

---- tests::greater_than_100 stdout ----
note: test did not panic as expected

failures:
    tests::greater_than_100

test result: FAILED. 0 passed; 1 failed; 0 ignored; 0 measured; 0 filtered out; finished in 0.00s

error: test failed, to rerun pass `--lib`
```

ما در این مورد پیام خیلی مفیدی دریافت نمی‌کنیم، اما وقتی به تابع تست نگاه می‌کنیم، می‌بینیم که با `#[should_panic]` حاشیه‌نویسی شده است. شکستی که گرفتیم به این معناست که کد در تابع تست باعث وحشت نشده است.

تست‌هایی که از `should_panic` استفاده می‌کنند می‌توانند نادقیق باشند. یک تست `should_panic` حتی اگر تست به دلیلی متفاوت از آنچه انتظار داشتیم وحشت کند موفق خواهد شد. برای دقیق‌تر کردن تست‌های `should_panic`، می‌توانیم یک پارامتر اختیاری `expected` به ویژگی `should_panic` اضافه کنیم. ابزار تست اطمینان حاصل خواهد کرد که پیام شکست شامل متن ارائه‌شده باشد. برای مثال، کد اصلاح‌شده برای `Guess` در **جدول 11-9** را در نظر بگیرید که تابع `new` با پیام‌های مختلفی بسته به اینکه مقدار خیلی کوچک باشد یا خیلی بزرگ، وحشت می‌کند.

**فایل: src/lib.rs**

```rust
// --قطعه کد حذف شده--

impl Guess {
    pub fn new(value: i32) -> Guess {
        if value < 1 {
            panic!(
                "Guess value must be greater than or equal to 1, got {value}."
            );
        } else if value > 100 {
            panic!(
                "Guess value must be less than or equal to 100, got {value}."
            );
        }

        Guess { value }
    }
}

#[cfg(test)]
mod tests {
    use super::*;

    #[test]
    #[should_panic(expected = "less than or equal to 100")]
    fn greater_than_100() {
        Guess::new(200);
    }
}
```

**جدول 11-9**: تست برای یک `panic!` با پیامی که شامل یک زیررشته مشخص‌شده است

این تست موفق خواهد شد زیرا مقداری که در پارامتر `expected` ویژگی `should_panic` قرار دادیم زیررشته‌ای از پیامی است که تابع `Guess::new` با آن وحشت می‌کند. می‌توانستیم کل پیام وحشتی که انتظار داریم را مشخص کنیم، که در این مورد `Guess value must be less than or equal to 100, got 200` خواهد بود. آنچه انتخاب می‌کنید برای مشخص کردن به این بستگی دارد که چه مقدار از پیام وحشت منحصربه‌فرد یا پویا است و چقدر می‌خواهید تست شما دقیق باشد. در این مورد، یک زیررشته از پیام وحشت کافی است تا اطمینان حاصل شود که کد در تابع تست مورد `else if value > 100` را اجرا می‌کند.

برای دیدن اینکه وقتی یک تست `should_panic` با یک پیام مورد انتظار شکست می‌خورد چه اتفاقی می‌افتد، بیایید دوباره یک باگ به کدمان معرفی کنیم با تعویض بدنه‌های بلاک‌های `if value < 1` و `else if value > 100`:

**این کد رفتار مورد نظر را تولید نمی‌کند.**

```rust
if value < 1 {
    panic!(
        "Guess value must be less than or equal to 100, got {value}."
    );
} else if value > 100 {
    panic!(
        "Guess value must be greater than or equal to 1, got {value}."
    );
}
```

این بار وقتی تست `should_panic` را اجرا کنیم، شکست خواهد خورد:

```bash
$ cargo test
   Compiling guessing_game v0.1.0 (file:///projects/guessing_game)
    Finished `test` profile [unoptimized + debuginfo] target(s) in 0.66s
     Running unittests src/lib.rs (target/debug/deps/guessing_game-57d70c3acb738f4d)

running 1 test
test tests::greater_than_100 - should panic ... FAILED

failures:

---- tests::greater_than_100 stdout ----

thread 'tests::greater_than_100' panicked at src/lib.rs:12:13:
Guess value must be greater than or equal to 1, got 200.
note: run with `RUST_BACKTRACE=1` environment variable to display a backtrace
note: panic did not contain expected string
      panic message: `"Guess value must be greater than or equal to 1, got 200."`,
 expected substring: `"less than or equal to 100"`

failures:
    tests::greater_than_100

test result: FAILED. 0 passed; 1 failed; 0 ignored; 0 measured; 0 filtered out; finished in 0.00s

error: test failed, to rerun pass `--lib`
```

پیام شکست نشان می‌دهد که این تست واقعاً همان‌طور که انتظار داشتیم وحشت کرد، اما پیام وحشت شامل رشته مورد انتظار `less than or equal to 100` نبود. پیامی وحشتی که در این مورد گرفتیم `Guess value must be greater than or equal to 1, got 200` بود. حالا می‌توانیم شروع به فهمیدن کنیم که باگ ما کجاست!

## استفاده از `Result<T, E>` در تست‌ها

تست‌های ما تا کنون همه وقتی شکست می‌خورند وحشت می‌کنند. ما همچنین می‌توانیم تست‌هایی بنویسیم که از `Result<T, E>` استفاده کنند! اینجا تست از **جدول 11-1** است، که دوباره نوشته شده تا از `Result<T, E>` استفاده کند و به‌جای وحشت کردن یک `Err` برگرداند:

```rust
#[test]
fn it_works() -> Result<(), String> {
    let result = add(2, 2);

    if result == 4 {
        Ok(())
    } else {
        Err(String::from("two plus two does not equal four"))
    }
}
```

تابع `it_works` اکنون نوع بازگشتی `Result<(), String>` دارد. در بدنه تابع، به‌جای فراخوانی ماکرو `assert_eq!`، وقتی تست موفق می‌شود `Ok(())` برمی‌گردانیم و وقتی تست شکست می‌خورد یک `Err` با یک `String` داخل آن.

نوشتن تست‌ها به‌گونه‌ای که `Result<T, E>` برگردانند به شما امکان می‌دهد از عملگر علامت سؤال (`?`) در بدنه تست‌ها استفاده کنید، که می‌تواند راهی راحت برای نوشتن تست‌هایی باشد که اگر هر عملیاتی در آن‌ها واریانت `Err` برگرداند باید شکست بخورند.

شما نمی‌توانید حاشیه‌نویسی `#[should_panic]` را روی تست‌هایی که از `Result<T, E>` استفاده می‌کنند به کار ببرید. برای تأیید اینکه یک عملیات واریانت `Err` برمی‌گرداند، از عملگر علامت سؤال روی مقدار `Result<T, E>` استفاده نکنید. به‌جای آن، از `assert!(value.is_err())` استفاده کنید.

اکنون که چند راه برای نوشتن تست‌ها می‌دانید، بیایید به آنچه هنگام اجرای تست‌هایمان اتفاق می‌افتد نگاه کنیم و گزینه‌های مختلفی که می‌توانیم با `cargo test` استفاده کنیم را بررسی کنیم.